Workbook

Sheet Valuation Dashboard
D1: =+Timeline!A2 -> #VALUE!
S3: METODOLOGIAS DE VALUACION
S5: A. | T5: VALOR PRESENT DE FLUJO DE FONDOS
T6: Proyeccion Proforma: | Z6: 2026-2030
D7: VALUACION INDICATIVA DE LA EMPRESA | T7: Tasa de descuento: | AA7: =+Engine!Q219 -> 0.161485
T8: Pertetuidad aplicada (USD): | AA8: =+J17 -> 9731762.4 | AI8: Pond.
D9: COMPANY VALUATION (Pre Money) | U9: Valuacion Obtenida: | AD9: =+Engine!Q223 -> 7185460.4 | AG9: USD | AI9: 0.6
D10: =+AD21/1000000 -> 6.6935852 | L10: M USD | M10: TRUE
S11: B. | T11: MULTIPLO DE EBITDA | AB11: 18.83 | AD11: Benchmark
T12: EBITDA 2025 (USD) | AA12: =+R38*1000 -> 301024.34
T13: Multimplo Aplicable: | AB13: =+Engine!Q227 -> 13
E14: Methodologia: | J14: VAN Perpetuidad | U14: Valuacion Obtenida: | AD14: =+Engine!Q229 -> 6294468.4 | AG14: USD | AI14: 0.3
E15: Tasa de descuento:
S16: C. | T16: MULTIPLO DE VENTAS | AB16: 2.36 | AD16: Benchmark
A17: TRUE | E17: Valor Aplicado: | J17: =+Engine!$AT$214 -> 9731762.4 | N17: USD | T17: VENTAS 2025 (USD) | AA17: =+Engine!Q233 -> 1646561.4
T18: Multimplo Aplicable: | AB18: =+Engine!Q232 -> 3 | AN18: VENTAS | BM18: EBITDA
E19: Aplicacion Perpetuidad: | U19: Valuacion Obtenida: | AD19: =+Engine!Q234 -> 4939684.2 | AG19: USD | AI19: =100%-AI9-AI14 -> 0.1 | AN19: 2023 | AQ19: 2024 | AT19: =+AQ19+1 -> 2025 | AW19: =+AT19+1 -> 2026 | AZ19: =+AW19+1 -> 2027 | BC19: =+AZ19+1 -> 2028 | BF19: =+BC19+1 -> 2029 | BI19: =+BF19+1 -> 2030 | BM19: 2023 | BP19: 2024 | BS19: =+BP19+1 -> 2025 | BV19: =+BS19+1 -> 2026 | BY19: =+BV19+1 -> 2027 | CB19: =+BY19+1 -> 2028 | CE19: =+CB19+1 -> 2029 | CH19: =+CE19+1 -> 2030
E20: Tasa de descuento: | K20: =+Engine!$Q$219 -> 0.161485 | AN20: =+SUMIFS(Engine!$O$175:$V$175,Engine!$O$163:$V$163,AN19) -> 666807.44 | AQ20: =+SUMIFS(Engine!$O$175:$V$175,Engine!$O$163:$V$163,AQ19) -> 919497.15 | AT20: =+SUMIFS(Engine!$O$175:$V$175,Engine!$O$163:$V$163,AT19) -> 1312010 | AW20: =+SUMIFS(Engine!$O$175:$V$175,Engine!$O$163:$V$163,AW19) -> 2153259.9 | AZ20: =+SUMIFS(Engine!$O$175:$V$175,Engine!$O$163:$V$163,AZ19) -> 3174238.2 | BC20: =+SUMIFS(Engine!$O$175:$V$175,Engine!$O$163:$V$163,BC19) -> 3972505.2 | BF20: =+SUMIFS(Engine!$O$175:$V$175,Engine!$O$163:$V$163,BF19) -> 4486353.7 | BI20: =+SUMIFS(Engine!$O$175:$V$175,Engine!$O$163:$V$163,BI19) -> 4780585.2 | BM20: =+SUMIFS(Engine!$O$262:$V$262,Engine!$O$163:$V$163,BM19) -> 206741.02 | BP20: =+SUMIFS(Engine!$O$262:$V$262,Engine!$O$163:$V$163,BP19) -> 203147.84 | BS20: =+SUMIFS(Engine!$O$262:$V$262,Engine!$O$163:$V$163,BS19) -> 301024.34 | BV20: =+SUMIFS(Engine!$O$262:$V$262,Engine!$O$163:$V$163,BV19) -> 551914.83 | BY20: =+SUMIFS(Engine!$O$262:$V$262,Engine!$O$163:$V$163,BY19) -> 827997.79 | CB20: =+SUMIFS(Engine!$O$262:$V$262,Engine!$O$163:$V$163,CB19) -> 1048977.7 | CE20: =+SUMIFS(Engine!$O$262:$V$262,Engine!$O$163:$V$163,CE19) -> 1193133.2 | CH20: =+SUMIFS(Engine!$O$262:$V$262,Engine!$O$163:$V$163,CH19) -> 1276274.6
E21: Tasa de Crecimiento: | K21: =+Engine!AT200 -> 0.06968331 | T21: VALUACION PONDERADA | AD21: =+AD9*AI9+AD14*AI14+AD19*AI19 -> 6693585.2 | AG21: USD | AI21: =+AI9+AI14+AI19 -> 1 | AQ21: =+(AQ20-AN20)/AN20 -> 0.37895455 | AT21: =+(AT20-AQ20)/AQ20 -> 0.42687769 | AW21: =+(AW20-AT20)/AT20 -> 0.64119171 | AZ21: =+(AZ20-AW20)/AW20 -> 0.4741547 | BC21: =+(BC20-AZ20)/AZ20 -> 0.25148304 | BF21: =+(BF20-BC20)/BC20 -> 0.12935124 | BI21: =+(BI20-BF20)/BF20 -> 0.065583657 | BP21: =+(BP20-BM20)/BM20 -> -0.017380107 | BS21: =+(BS20-BP20)/BP20 -> 0.4817994 | BV21: =+(BV20-BS20)/BS20 -> 0.83345581 | BY21: =+(BY20-BV20)/BV20 -> 0.50022748 | CB21: =+(CB20-BY20)/BY20 -> 0.26688467 | CE21: =+(CE20-CB20)/CB20 -> 0.13742471 | CH21: =+(CH20-CE20)/CE20 -> 0.06968331
E22: Valor Perpetuidad: | J22: =+Engine!$AT$214/(1-K23) -> 9731762.4 | N22: USD
Q23: Directorio | W23: ANDESMAR INCL. | AC23: Ajuste Costos Andesmar | AI23: 0.015 | AY23: Atemperador
AN24: AJUSTE CURVA DE CRECIMIENTO | AY24: 1 | BB24: 1.5 | BE24: 2 | BH24: 2 | BK24: 2
AN25: % sobre ventas Acumuladas | AV25: 2025 | AY25: 2026 | BB25: =+AY25+1 -> 2027 | BE25: =+BB25+1 -> 2028 | BH25: =+BE25+1 -> 2029 | BK25: =+BH25+1 -> 2030
E26: PROYECCIONES FINANCIERAS | M26: 2023 | P26: =+M26+1 -> 2024 | S26: =+P26+1 -> 2025 | V26: =+S26+1 -> 2026 | Y26: =+V26+1 -> 2027 | AB26: =+Y26+1 -> 2028 | AE26: =+AB26+1 -> 2029 | AH26: =+AE26+1 -> 2030 | AN26: =+Engine!N142 -> TOLWEB SaaS | AS26: Q1 | AV26: =+Engine!W142 -> 2.4493832 | AY26: =+Engine!AA142 -> 1.1118614 | BB26: =+Engine!AE142 -> 0.74124092 | BE26: =+Engine!AI142 -> 0.37062046 | BH26: =+Engine!AM142 -> 0.18531023 | BK26: =+Engine!AQ142 -> 0.092655115
E27: Valores en Miles de Dolares | M27: Año -2 | P27: Año -1 | S27: Año 0 | V27: Año 1 | Y27: Año 2 | AB27: Año 3 | AE27: Año 4 | AH27: Año 5 | AS27: Q2 | AV27: =+Engine!X142 -> 2.2648922 | AY27: =+Engine!AB142 -> 1.1184093 | BB27: =+Engine!AF142 -> 0.74560622 | BE27: =+Engine!AJ142 -> 0.37280311 | BH27: =+Engine!AN142 -> 0.18640155 | BK27: =+Engine!AR142 -> 0.093200777
E28: Ingresos | AS28: Q3 | AV28: =+Engine!Y142 -> 1.4408391 | AY28: =+Engine!AC142 -> 0.88730174 | BB28: =+Engine!AG142 -> 0.59153449 | BE28: =+Engine!AK142 -> 0.29576725 | BH28: =+Engine!AO142 -> 0.14788362 | BK28: =+Engine!AS142 -> 0.073941812
E29: TOLWEB | M29: =+SUMIFS(Engine!$O$126:$AT$126,Engine!$O$121:$AT$121,M$26)/1000 -> 353.89966 | O29: =+SUMIFS(Engine!$O$126:$AT$126,Engine!$O$121:$AT$121,P26)/1000 -> 485.87652 | R29: =+SUMIFS(Engine!$O$126:$AT$126,Engine!$O$121:$AT$121,S$26)/1000 -> 923.88919 | U29: =+SUMIFS(Engine!$O$126:$AT$126,Engine!$O$121:$AT$121,V$26)/1000 -> 1698.887 | X29: =+SUMIFS(Engine!$O$126:$AT$126,Engine!$O$121:$AT$121,Y$26)/1000 -> 2663.1139 | AA29: =+SUMIFS(Engine!$O$126:$AT$126,Engine!$O$121:$AT$121,AB$26)/1000 -> 3427.4862 | AD29: =+SUMIFS(Engine!$O$126:$AT$126,Engine!$O$121:$AT$121,AE$26)/1000 -> 3922.7144 | AG29: =+SUMIFS(Engine!$O$126:$AT$126,Engine!$O$121:$AT$121,AH$26)/1000 -> 4207.1729 | AS29: Q4 | AV29: =+Engine!Z142 -> -0.088019356 | AY29: =+Engine!AD142 -> 0.62326699 | BB29: =+Engine!AH142 -> 0.41551132 | BE29: =+Engine!AL142 -> 0.20775566 | BH29: =+Engine!AP142 -> 0.10387783 | BK29: =+Engine!AT142 -> 0.051938916
E30: TOLPOS | M30: =+SUMIFS(Engine!$O$130:$AT$130,Engine!$O$121:$AT$121,M$26)/1000 -> 0 | P30: =+SUMIFS(Engine!$O$130:$AT$130,Engine!$O$121:$AT$121,P26)/1000 -> 0 | R30: =+SUMIFS(Engine!$O$130:$AT$130,Engine!$O$121:$AT$121,S$26)/1000 -> 0 | U30: =+SUMIFS(Engine!$O$130:$AT$130,Engine!$O$121:$AT$121,V$26)/1000 -> 0 | X30: =+SUMIFS(Engine!$O$130:$AT$130,Engine!$O$121:$AT$121,Y$26)/1000 -> 0 | AA30: =+SUMIFS(Engine!$O$130:$AT$130,Engine!$O$121:$AT$121,AB$26)/1000 -> 0 | AD30: =+SUMIFS(Engine!$O$130:$AT$130,Engine!$O$121:$AT$121,AE$26)/1000 -> 0 | AG30: =+SUMIFS(Engine!$O$130:$AT$130,Engine!$O$121:$AT$121,AH$26)/1000 -> 0 | AN30: =+Engine!N146 -> TOLPOS SaaS | AS30: Q1 | AV30: =+Engine!W146 -> 0.46023771 | AY30: =+Engine!AA146 -> 0.18519056 | BB30: =+Engine!AE146 -> 0.12346038 | BE30: =+Engine!AI146 -> 0.061730188 | BH30: =+Engine!AM146 -> 0.030865094 | BK30: =+Engine!AQ146 -> 0.015432547
E31: UNIBUS | M31: =+SUMIFS(Engine!$O$134:$AT$134,Engine!$O$121:$AT$121,M$26)/1000 -> 312.90778 | P31: =+SUMIFS(Engine!$O$134:$AT$134,Engine!$O$121:$AT$121,P26)/1000 -> 433.62063 | R31: =+SUMIFS(Engine!$O$134:$AT$134,Engine!$O$121:$AT$121,S$26)/1000 -> 388.12077 | U31: =+SUMIFS(Engine!$O$134:$AT$134,Engine!$O$121:$AT$121,V$26)/1000 -> 454.37289 | X31: =+SUMIFS(Engine!$O$134:$AT$134,Engine!$O$121:$AT$121,Y$26)/1000 -> 511.1243 | AA31: =+SUMIFS(Engine!$O$134:$AT$134,Engine!$O$121:$AT$121,AB$26)/1000 -> 545.01899 | AD31: =+SUMIFS(Engine!$O$134:$AT$134,Engine!$O$121:$AT$121,AE$26)/1000 -> 563.63926 | AG31: =+SUMIFS(Engine!$O$134:$AT$134,Engine!$O$121:$AT$121,AH$26)/1000 -> 573.41231 | AS31: Q2 | AV31: =+Engine!X146 -> 0.73696351 | AY31: =+Engine!AB146 -> 0.70994269 | BB31: =+Engine!AF146 -> 0.47329513 | BE31: =+Engine!AJ146 -> 0.23664756 | BH31: =+Engine!AN146 -> 0.11832378 | BK31: =+Engine!AR146 -> 0.059161891
E32: Total Ingresos | M32: =SUM(M29:N31) -> 666.80744 | P32: =SUM(P29:Q31) -> 433.62063 | R32: =SUM(R29:T31) -> 1312.01 | U32: =SUM(U29:W31) -> 2153.2599 | X32: =SUM(X29:Z31) -> 3174.2382 | AA32: =SUM(AA29:AC31) -> 3972.5052 | AD32: =SUM(AD29:AF31) -> 4486.3537 | AG32: =SUM(AG29:AI31) -> 4780.5852 | AS32: Q3 | AV32: =+Engine!Y146 -> -0.87235005 | AY32: =+Engine!AC146 -> -0.033005778 | BB32: =+Engine!AG146 -> -0.022003852 | BE32: =+Engine!AK146 -> -0.011001926 | BH32: =+Engine!AO146 -> -0.0055009629 | BK32: =+Engine!AS146 -> -0.0027504815
E33: Costos | AS33: Q4 | AV33: =+Engine!Z146 -> -1 | AY33: =+Engine!AD146 -> -0.2420286 | BB33: =+Engine!AH146 -> -0.1613524 | BE33: =+Engine!AL146 -> -0.080676199 | BH33: =+Engine!AP146 -> -0.0403381 | BK33: =+Engine!AT146 -> -0.02016905
E34: TOLWEB | F34: =+Engine!N187 -> OPERACIONES | M34: =+SUMIFS(Engine!$O$187:$AT$187,Engine!$O$121:$AT$121,M$26)/1000 -> 73.415951 | O34: =+SUMIFS(Engine!$O$187:$AT$187,Engine!$O$121:$AT$121,P$26)/1000 -> 112.8959 | R34: =+SUMIFS(Engine!$O$187:$AT$187,Engine!$O$121:$AT$121,S$26)/1000 -> 175.26955 | U34: =+SUMIFS(Engine!$O$187:$AT$187,Engine!$O$121:$AT$121,V$26)/1000 -> 262.85167 | X34: =+SUMIFS(Engine!$O$187:$AT$187,Engine!$O$121:$AT$121,Y$26)/1000 -> 391.18836 | AA34: =+SUMIFS(Engine!$O$187:$AT$187,Engine!$O$121:$AT$121,AB$26)/1000 -> 492.61621 | AD34: =+SUMIFS(Engine!$O$187:$AT$187,Engine!$O$121:$AT$121,AE$26)/1000 -> 558.32513 | AG34: =+SUMIFS(Engine!$O$187:$AT$187,Engine!$O$121:$AT$121,AH$26)/1000 -> 596.08389 | AN34: =+Engine!N150 -> Plataforma UNIBUS | AS34: Q1 | AV34: =+Engine!W150 -> -0.26276888 | AY34: =+Engine!AA150 -> 0.0070057875 | BB34: =+Engine!AE150 -> 0.004670525 | BE34: =+Engine!AI150 -> 0.0023352625 | BH34: =+Engine!AM150 -> 0.0011676313 | BK34: =+Engine!AQ150 -> 0.00058381563
E35: TOLPOS | F35: =+Engine!N188 -> INFRAESTRUCTURA | M35: =+SUMIFS(Engine!$O$188:$AT$188,Engine!$O$121:$AT$121,M$26)/1000 -> 119.1956 | O35: =+SUMIFS(Engine!$O$126:$AT$126,Engine!$O$121:$AT$121,P$26)/1000 -> 485.87652 | R35: =+SUMIFS(Engine!$O$188:$AT$188,Engine!$O$121:$AT$121,S$26)/1000 -> 281.70995 | U35: =+SUMIFS(Engine!$O$188:$AT$188,Engine!$O$121:$AT$121,V$26)/1000 -> 435.3959 | X35: =+SUMIFS(Engine!$O$188:$AT$188,Engine!$O$121:$AT$121,Y$26)/1000 -> 637.28051 | AA35: =+SUMIFS(Engine!$O$188:$AT$188,Engine!$O$121:$AT$121,AB$26)/1000 -> 793.601 | AD35: =+SUMIFS(Engine!$O$188:$AT$188,Engine!$O$121:$AT$121,AE$26)/1000 -> 893.66553 | AG35: =+SUMIFS(Engine!$O$188:$AT$188,Engine!$O$121:$AT$121,AH$26)/1000 -> 950.78943 | AS35: Q2 | AV35: =+Engine!X150 -> 0.26826886 | AY35: =+Engine!AB150 -> 0.35430475 | BB35: =+Engine!AF150 -> 0.23620317 | BE35: =+Engine!AJ150 -> 0.11810158 | BH35: =+Engine!AN150 -> 0.059050791 | BK35: =+Engine!AR150 -> 0.029525396
E36: UNIBUS | F36: =+Engine!N189 -> PERSONAL | M36: =+SUMIFS(Engine!$O$189:$AT$189,Engine!$O$121:$AT$121,M$26)/1000 -> 267.45487 | O36: =+SUMIFS(Engine!$O$126:$AT$126,Engine!$O$121:$AT$121,P$26)/1000 -> 485.87652 | R36: =+SUMIFS(Engine!$O$189:$AT$189,Engine!$O$121:$AT$121,S$26)/1000 -> 554.00612 | U36: =+SUMIFS(Engine!$O$189:$AT$189,Engine!$O$121:$AT$121,V$26)/1000 -> 903.09748 | X36: =+SUMIFS(Engine!$O$189:$AT$189,Engine!$O$121:$AT$121,Y$26)/1000 -> 1317.7715 | AA36: =+SUMIFS(Engine!$O$189:$AT$189,Engine!$O$121:$AT$121,AB$26)/1000 -> 1637.3103 | AD36: =+SUMIFS(Engine!$O$189:$AT$189,Engine!$O$121:$AT$121,AE$26)/1000 -> 1841.2299 | AG36: =+SUMIFS(Engine!$O$189:$AT$189,Engine!$O$121:$AT$121,AH$26)/1000 -> 1957.4372 | AS36: Q3 | AV36: =+Engine!Y150 -> -0.096218859 | AY36: =+Engine!AC150 -> 0.27909767 | BB36: =+Engine!AG150 -> 0.18606512 | BE36: =+Engine!AK150 -> 0.093032558 | BH36: =+Engine!AO150 -> 0.046516279 | BK36: =+Engine!AS150 -> 0.023258139
E37: Total Costos | M37: =SUM(M34:N36) -> 460.06642 | O37: =SUM(O34:Q36) -> 1084.6489 | R37: =SUM(R34:T36) -> 1010.9856 | U37: =SUM(U34:W36) -> 1601.345 | X37: =SUM(X34:Z36) -> 2346.2404 | AA37: =SUM(AA34:AC36) -> 2923.5275 | AD37: =SUM(AD34:AF36) -> 3293.2205 | AG37: =SUM(AG34:AI36) -> 3504.3106 | AS37: Q4 | AV37: =+Engine!Z150 -> -0.14440828 | AY37: =+Engine!AD150 -> 0.093910975 | BB37: =+Engine!AH150 -> 0.062607317 | BE37: =+Engine!AL150 -> 0.031303658 | BH37: =+Engine!AP150 -> 0.015651829 | BK37: =+Engine!AT150 -> 0.0078259146
E38: EBITDA | M38: =+M32-M37 -> 206.74102 | O38: =+P32-O37 -> -651.02831 | R38: =+R32-R37 -> 301.02434 | U38: =+U32-U37 -> 551.91483 | X38: =+X32-X37 -> 827.99779 | AA38: =+AA32-AA37 -> 1048.9777 | AD38: =+AD32-AD37 -> 1193.1332 | AG38: =+AG32-AG37 -> 1276.2746
E39: Depreciaciones/Amortizaciones | M39: 0 | O39: 0 | R39: 0 | U39: 0 | X39: 0 | AA39: 0 | AD39: 0 | AG39: 0
E40: Intereses Financieros | M40: 0 | O40: 0 | R40: 0 | U40: 0 | X40: 0 | AA40: 0 | AD40: 0 | AG40: 0
E41: Ganancia antes de Impuestos | M41: =+M38-M39-M40 -> 206.74102 | O41: =+O38-O39-O40 -> -651.02831 | R41: =+R38-R39-R40 -> 301.02434 | U41: =+U38-U39-U40 -> 551.91483 | X41: =+X38-X39-X40 -> 827.99779 | AA41: =+AA38-AA39-AA40 -> 1048.9777 | AD41: =+AD38-AD39-AD40 -> 1193.1332 | AG41: =+AG38-AG39-AG40 -> 1276.2746 | AN41: ESTADOS CONTABLES HISTORICOS | AW41: 2021 | AZ41: 2022 | BC41: 2023 | BF41: 2024
E42: Impuestos | I42: 0.35 | M42: =+M41*I42 -> 72.359356 | O42: =+MAX(0,O41*I42) -> 0 | R42: =+R41*$I$42 -> 105.35852 | U42: =+U41*$I$42 -> 193.17019 | X42: =+X41*$I$42 -> 289.79923 | AA42: =+AA41*$I$42 -> 367.1422 | AD42: =+AD41*$I$42 -> 417.59661 | AG42: =+AG41*$I$42 -> 446.69612 | AU42: TC-BoP | AW42: 160 | AZ42: 210 | BC42: 360 | BF42: 995
...

Sheet Sheet1
F4: V A L U A C I O N
J7: Agosto 2025
G8: =+'Valuation Dashboard'!D1 -> #VALUE!
G17: =+'Valuation Dashboard'!D10*1000000 -> 6693585.2
G21: Plataforma integral para la comercialización y distribución de servicios de autobuses interurbanos y otras modalidades de movilidad. Modelo de Negocio Dual (B2C: UNIBUS; B2B: TOLWEB, TOLPOS, TOL API)

Sheet Timeline
A2: #VALUE! | I2: Year | J2: 2023 | K2: =+YEAR(K4) -> 2023 | L2: =+YEAR(L4) -> 2023 | M2: =+YEAR(M4) -> 2023 | N2: =+YEAR(N4) -> 2023 | O2: =+YEAR(O4) -> 2023 | P2: =+YEAR(P4) -> 2023 | Q2: =+YEAR(Q4) -> 2023 | R2: =+YEAR(R4) -> 2023 | ... DA2: =+YEAR(DA4) -> 2030
D3: PROYECCIONES FINANCIERAS | H3: Powered by: | I3: Project month | J3: =+ROUND(+(J4-$E$9)/30,0) -> -30 | K3: =+ROUND(+(K4-$E$9)/30,0) -> -29 | L3: =+ROUND(+(L4-$E$9)/30,0) -> -28 | M3: =+ROUND(+(M4-$E$9)/30,0) -> -27 | N3: =+ROUND(+(N4-$E$9)/30,0) -> -26 | O3: =+ROUND(+(O4-$E$9)/30,0) -> -25 | P3: =+ROUND(+(P4-$E$9)/30,0) -> -24 | Q3: =+ROUND(+(Q4-$E$9)/30,0) -> -23 | ... DA3: =+ROUND(+(DA4-$E$9)/30,0) -> 66
H4: #VALUE! | I4: Start | J4: 44927 | K4: =+J5+1 -> 44958 | L4: =+K5+1 -> 44986 | M4: =+L5+1 -> 45017 | N4: =+M5+1 -> 45047 | O4: =+N5+1 -> 45078 | P4: =+O5+1 -> 45108 | Q4: =+P5+1 -> 45139 | R4: =+Q5+1 -> 45170 | ... DA4: =+CZ5+1 -> 47818
I5: End | J5: =+EOMONTH(J4,0) -> 44957 | K5: =+EOMONTH(K4,0) -> 44985 | L5: =+EOMONTH(L4,0) -> 45016 | M5: =+EOMONTH(M4,0) -> 45046 | N5: =+EOMONTH(N4,0) -> 45077 | O5: =+EOMONTH(O4,0) -> 45107 | P5: =+EOMONTH(P4,0) -> 45138 | Q5: =+EOMONTH(Q4,0) -> 45169 | ... DA5: =+EOMONTH(DA4,0) -> 47848
J6: Q1 | K6: Q1 | L6: Q1 | M6: Q2 | N6: Q2 | O6: Q2 | P6: Q3 | Q6: Q3 | R6: Q3 | S6: Q4 | T6: Q4 | U6: Q4 | V6: Q1 | W6: Q1 | X6: Q1 | Y6: Q2 | Z6: Q2 | AA6: Q2 | AB6: Q3 | AC6: Q3 | AD6: Q3 | AE6: Q4 | AF6: Q4 | AG6: Q4 | AH6: Q1 | AI6: Q1 | AJ6: Q1 | AK6: Q2 | AL6: Q2 | AM6: Q2 | AN6: Q3 | AO6: Q3 | AP6: Q3 | AQ6: Q4 | AR6: Q4 | AS6: Q4 | AT6: Q1 | AU6: Q1 | AV6: Q1 | AW6: Q2 | AX6: Q2 | AY6: Q2 | AZ6: Q3 | BA6: Q3 | BB6: Q3 | BC6: Q4 | BD6: Q4 | BE6: Q4 | BF6: Q1 | BG6: Q1 | BH6: Q1 | BI6: Q2 | BJ6: Q2 | BK6: Q2 | BL6: Q3 | BM6: Q3 | BN6: Q3 | BO6: Q4 | BP6: Q4 | BQ6: Q4 | BR6: Q1 | BS6: Q1 | BT6: Q1 | BU6: Q2 | BV6: Q2 | BW6: Q2 | BX6: Q3 | BY6: Q3 | BZ6: Q3 | CA6: Q4 | CB6: Q4 | CC6: Q4 | CD6: Q1 | CE6: Q1 | CF6: Q1 | CG6: Q2 | CH6: Q2 | CI6: Q2 | CJ6: Q3 | CK6: Q3 | CL6: Q3 | CM6: Q4 | CN6: Q4 | CO6: Q4 | CP6: Q1 | CQ6: Q1 | CR6: Q1 | CS6: Q2 | CT6: Q2 | CU6: Q2 | CV6: Q3 | CW6: Q3 | CX6: Q3 | CY6: Q4 | CZ6: Q4 | DA6: Q4
I7: Inflation % | J7: =+SUMIFS('Curva Dolar Blue'!$S:$S,'Curva Dolar Blue'!$Q:$Q,Timeline!J4) -> 0.06 | K7: =+SUMIFS('Curva Dolar Blue'!$S:$S,'Curva Dolar Blue'!$Q:$Q,Timeline!K4) -> 0.066 | L7: =+SUMIFS('Curva Dolar Blue'!$S:$S,'Curva Dolar Blue'!$Q:$Q,Timeline!L4) -> 0.077 | M7: =+SUMIFS('Curva Dolar Blue'!$S:$S,'Curva Dolar Blue'!$Q:$Q,Timeline!M4) -> 0.084 | N7: =+SUMIFS('Curva Dolar Blue'!$S:$S,'Curva Dolar Blue'!$Q:$Q,Timeline!N4) -> 0.078 | O7: =+SUMIFS('Curva Dolar Blue'!$S:$S,'Curva Dolar Blue'!$Q:$Q,Timeline!O4) -> 0.06 | P7: =+SUMIFS('Curva Dolar Blue'!$S:$S,'Curva Dolar Blue'!$Q:$Q,Timeline!P4) -> 0.063 | Q7: =+SUMIFS('Curva Dolar Blue'!$S:$S,'Curva Dolar Blue'!$Q:$Q,Timeline!Q4) -> 0.124 | ... AL7: =+SUMIFS('Curva Dolar Blue'!$S:$S,'Curva Dolar Blue'!$Q:$Q,Timeline!AL4) -> 0 | AM7: =+AL7 -> 0 | AN7: =+AM7 -> 0 | AO7: =+AN7 -> 0 | AP7: =+AO7 -> 0 | AQ7: =+AP7 -> 0 | AR7: =+AQ7 -> 0 | AS7: =+AR7 -> 0 | AT7: =+AS7 -> 0 | ... DA7: =+CZ7 -> 0
I8: Cum Factor | J8: =+IF(J4<$E$9,1,I8*(1+J7)) -> 1 | K8: =+IF(K4<$E$9,1,J8*(1+K7)) -> 1 | L8: =+IF(L4<$E$9,1,K8*(1+L7)) -> 1 | M8: =+IF(M4<$E$9,1,L8*(1+M7)) -> 1 | N8: =+IF(N4<$E$9,1,M8*(1+N7)) -> 1 | O8: =+IF(O4<$E$9,1,N8*(1+O7)) -> 1 | P8: =+IF(P4<$E$9,1,O8*(1+P7)) -> 1 | Q8: =+IF(Q4<$E$9,1,P8*(1+Q7)) -> 1 | ... DA8: =+IF(DA4<$E$9,1,CZ8*(1+DA7)) -> 1
D9: Fecha de Inicio | E9: 45839 | G9: (mes 0) | I9: Dolar Oficial | J9: =+SUMIFS('Curva Dolar Blue'!$L:$L,'Curva Dolar Blue'!$K:$K,Timeline!J5) -> 186.875 | K9: =+SUMIFS('Curva Dolar Blue'!$L:$L,'Curva Dolar Blue'!$K:$K,Timeline!K5) -> 197.1533 | L9: =+SUMIFS('Curva Dolar Blue'!$L:$L,'Curva Dolar Blue'!$K:$K,Timeline!L5) -> 208.9883 | M9: =+SUMIFS('Curva Dolar Blue'!$L:$L,'Curva Dolar Blue'!$K:$K,Timeline!M5) -> 222.575 | N9: =+SUMIFS('Curva Dolar Blue'!$L:$L,'Curva Dolar Blue'!$K:$K,Timeline!N5) -> 239.325 | O9: =+SUMIFS('Curva Dolar Blue'!$L:$L,'Curva Dolar Blue'!$K:$K,Timeline!O5) -> 256.675 | P9: =+SUMIFS('Curva Dolar Blue'!$L:$L,'Curva Dolar Blue'!$K:$K,Timeline!P5) -> 275.2833 | Q9: =+SUMIFS('Curva Dolar Blue'!$L:$L,'Curva Dolar Blue'!$K:$K,Timeline!Q5) -> 350.0167 | ... AS9: =+SUMIFS('Curva Dolar Blue'!$L:$L,'Curva Dolar Blue'!$K:$K,Timeline!AS5) -> 1443 | AT9: =+AS9 -> 1443 | AU9: =+AT9 -> 1443 | AV9: =+AU9 -> 1443 | AW9: =+AV9 -> 1443 | AX9: =+AW9 -> 1443 | AY9: =+AX9 -> 1443 | AZ9: =+AY9 -> 1443 | BA9: =+AZ9 -> 1443 | ... DA9: =+CZ9 -> 1443 | DB9: TOTAL
I10: Dolar Blue | J10: =+SUMIFS('Curva Dolar Blue'!$G:$G,'Curva Dolar Blue'!$F:$F,Timeline!J5) -> 382 | K10: =+SUMIFS('Curva Dolar Blue'!$G:$G,'Curva Dolar Blue'!$F:$F,Timeline!K5) -> 375 | L10: =+SUMIFS('Curva Dolar Blue'!$G:$G,'Curva Dolar Blue'!$F:$F,Timeline!L5) -> 393 | M10: =+SUMIFS('Curva Dolar Blue'!$G:$G,'Curva Dolar Blue'!$F:$F,Timeline!M5) -> 468 | N10: =+SUMIFS('Curva Dolar Blue'!$G:$G,'Curva Dolar Blue'!$F:$F,Timeline!N5) -> 490 | O10: =+SUMIFS('Curva Dolar Blue'!$G:$G,'Curva Dolar Blue'!$F:$F,Timeline!O5) -> 493 | P10: =+SUMIFS('Curva Dolar Blue'!$G:$G,'Curva Dolar Blue'!$F:$F,Timeline!P5) -> 550 | Q10: =+SUMIFS('Curva Dolar Blue'!$G:$G,'Curva Dolar Blue'!$F:$F,Timeline!Q5) -> 730 | ... DA10: =+SUMIFS('Curva Dolar Blue'!$G:$G,'Curva Dolar Blue'!$F:$F,Timeline!DA5) -> 0
A13: 1 | C13: VENTAS HISTORICAS | D13: en AR$ | E13: HISTORICO
C15: VENTAS HISTORICAS | D15: TOTALES EN PESOS | G15: Total 2023 - 2025
B17: 1 | C17: TOLWEB SaaS | G17: =SUM(J17:AS17) -> 2.6626288e+09 | H17: =+G17/$G$20 -> 0.65491543 | I17: AR$ | J17: 30394935 | K17: 19249470 | L17: 14315810 | M17: 12755003 | N17: 11614809 | O17: 11414492 | P17: 18124702 | Q17: 15396306 | R17: 21226326 | S17: 27009622 | T17: 39017414 | U17: 66360955 | V17: 54349483 | W17: 44146828 | X17: 41638298 | Y17: 23415888 | Z17: 26737566 | AA17: 37916152 | AB17: 52642707 | AC17: 35840535 | AD17: 50733844 | AE17: 68042942 | AF17: 1.1329965e+08 | AG17: 2.0246708e+08 | AH17: 2.5547975e+08 | AI17: 1.8277755e+08 | AJ17: 1.1781852e+08 | AK17: 1.0630974e+08 | AL17: 70247179 | AM17: 1.04402e+08 | AN17: 1.4282822e+08 | AO17: 1.1552043e+08 | AP17: 1.0060633e+08 | AQ17: 98731153 | AR17: 1.3596149e+08 | AS17: 1.9383565e+08
B18: 2 | C18: TOLPOS SaaS | G18: =SUM(J18:AS18) -> 1.8423755e+08 | H18: =+G18/$G$20 -> 0.045316122 | I18: AR$ | J18: 3497853.2 | K18: 2215231.6 | L18: 1647465.3 | M18: 1467847.5 | N18: 1336633.8 | O18: 1313581.3 | P18: 2085793.2 | Q18: 1771809 | R18: 2442728.5 | S18: 3108271 | T18: 4490129.3 | U18: 7636827.7 | V18: 6695806.4 | W18: 5978176.3 | X18: 6179658.8 | Y18: 5096852.2 | Z18: 5824580.8 | AA18: 6438583 | AB18: 8121611.4 | AC18: 6723016.3 | AD18: 6906396.7 | AE18: 7547652.2 | AF18: 9540187.1 | AG18: 11404994 | AH18: 12139961 | AI18: 10742831 | AJ18: 9151657.9 | AK18: 9482688.2 | AL18: 8088755.3 | AM18: 12239633 | AN18: 1292904 | AO18: 864342.59 | AP18: 763085.58 | AQ18: 0 | AR18: 0 | AS18: 0
B19: 3 | C19: Plataforma UNIBUS | G19: =SUM(J19:AS19) -> 1.2187407e+09 | H19: =+G19/$G$20 -> 0.29976844 | I19: AR$ | J19: 20667399 | K19: 13088907 | L19: 9734205.7 | M19: 8672916.4 | N19: 7897628.2 | O19: 7761420 | P19: 12324108 | Q19: 10468902 | R19: 14433094 | S19: 18365515 | T19: 26530357 | U19: 45122924 | V19: 72482803 | W19: 47199724 | X19: 39174621 | Y19: 28058736 | Z19: 25939260 | AA19: 33462032 | AB19: 35223556 | AC19: 36027855 | AD19: 45636218 | AE19: 51090895 | AF19: 49055097 | AG19: 47451919 | AH19: 53444844 | AI19: 43608163 | AJ19: 36880265 | AK19: 33702854 | AL19: 42665459 | AM19: 33359007 | AN19: 34387046 | AO19: 34292670 | AP19: 44531767 | AQ19: 48857775 | AR19: 52740461 | AS19: 54400307
C20: Totales | G20: =SUM(J20:AS20) -> 4.0656071e+09 | H20: =+G20/$G$20 -> 1 | I20: AR$ | J20: =SUM(J17:J19) -> 54560186 | K20: =SUM(K17:K19) -> 34553608 | L20: =SUM(L17:L19) -> 25697481 | M20: =SUM(M17:M19) -> 22895767 | N20: =SUM(N17:N19) -> 20849071 | O20: =SUM(O17:O19) -> 20489493 | P20: =SUM(P17:P19) -> 32534603 | Q20: =SUM(Q17:Q19) -> 27637017 | ... AS20: =SUM(AS17:AS19) -> 2.4823596e+08
C22: Andesmar Total | G22: =SUM(J22:AS22) -> 8.9839184e+08 | H22: =G22/G20 -> 0.2209736 | I22: AR$ | J22: =J43+J38+J33 -> 12295217 | K22: =K43+K38+K33 -> 7786705.6 | L22: =L43+L38+L33 -> 5790964.5 | M22: =M43+M38+M33 -> 5159594.2 | N22: =N43+N38+N33 -> 4698368.4 | O22: =O43+O38+O33 -> 4617337 | P22: =P43+P38+P33 -> 7331719.8 | Q22: =Q43+Q38+Q33 -> 6228041.8 | ... AG22: =AG43+AG38+AG33 -> 62247678 | AH22: 79333353 | AI22: 58585727 | AJ22: 44719359 | AK22: 41324837 | AL22: 33460086 | AM22: 59055936 | AN22: 68275150 | AO22: 53387115 | AP22: 37662894 | AQ22: 2650382.3 | AR22: 0 | AS22: 0
C24: Totales SIN Andesmar | G24: =SUM(J24:AS24) -> 3.1672152e+09 | H24: =+G24/$G$20 -> 0.7790264 | I24: AR$ | J24: =+J20-J22 -> 42264969 | K24: =+K20-K22 -> 26766902 | L24: =+L20-L22 -> 19906516 | M24: =+M20-M22 -> 17736173 | N24: =+N20-N22 -> 16150703 | O24: =+O20-O22 -> 15872156 | P24: =+P20-P22 -> 25202883 | Q24: =+Q20-Q22 -> 21408975 | ... AS24: =+AS20-AS22 -> 2.4823596e+08
C26: Incidencia Andesmar | G26: =+G22/G20 -> 0.2209736 | I26: % | J26: =+J22/J20 -> 0.22535145 | K26: =+K22/K20 -> 0.22535145 | L26: =+L22/L20 -> 0.22535145 | M26: =+M22/M20 -> 0.22535145 | N26: =+N22/N20 -> 0.22535145 | O26: =+O22/O20 -> 0.22535145 | P26: =+P22/P20 -> 0.22535145 | Q26: =+Q22/Q20 -> 0.22535145 | ... AS26: =+AS22/AS20 -> 0
C30: VENTAS HISTORICAS | D30: DETALLE POR UNIDADES
B32: 1 | C32: TOLWEB SaaS | E32: =+H17 -> 0.65491543 | G32: =SUM(J32:AS32) -> 2.6626288e+09 | H32: 1 | I32: AR$ | J32: =J17 -> 30394935 | K32: =K17 -> 19249470 | L32: =L17 -> 14315810 | M32: =M17 -> 12755003 | N32: =N17 -> 11614809 | O32: =O17 -> 11414492 | P32: =P17 -> 18124702 | Q32: =Q17 -> 15396306 | ... AS32: =AS17 -> 1.9383565e+08
C33: Andesmar - TOLWEB | G33: =SUM(J33:AS33) -> 6.4084161e+08 | H33: =G33/$G$32 -> 0.24068004 | I33: AR$ | J33: =J281 -> 7020043.7 | K33: =K281 -> 4445876.2 | L33: =L281 -> 3306393.3 | M33: =M281 -> 2945907.9 | N33: =N281 -> 2682567.7 | O33: =O281 -> 2636302.2 | P33: =P281 -> 4186098.8 | Q33: =Q281 -> 3555945.8 | ... AG33: =AG281 -> 46761994 | AH33: 67193392 | AI33: 47842896 | AJ33: 35567701 | AK33: 31842149 | AL33: 25371330 | AM33: 45385390 | AN33: 60970618 | AO33: 47354855 | AP33: 36899808 | AQ33: 2650382.3
C34: TOLWEB SaaS sin Andesmar | G34: =SUM(J34:AS34) -> 2.0217872e+09 | H34: =H32-H33 -> 0.75931996 | I34: AR$ | J34: =J32-J33 -> 23374891 | K34: =K32-K33 -> 14803593 | L34: =L32-L33 -> 11009416 | M34: =M32-M33 -> 9809095 | N34: =N32-N33 -> 8932241.6 | O34: =O32-O33 -> 8778189.8 | P34: =P32-P33 -> 13938603 | Q34: =Q32-Q33 -> 11840360 | ... AS34: =AS32-AS33 -> 1.9383565e+08
C35: Incidencia Andesmar | G35: =+G33/G32 -> 0.24068004 | I35: % | J35: =+J33/J32 -> 0.23096097 | K35: =+K33/K32 -> 0.23096097 | L35: =+L33/L32 -> 0.23096097 | M35: =+M33/M32 -> 0.23096097 | N35: =+N33/N32 -> 0.23096097 | O35: =+O33/O32 -> 0.23096097 | P35: =+P33/P32 -> 0.23096097 | Q35: =+Q33/Q32 -> 0.23096097 | ... AS35: =+AS33/AS32 -> 0
B37: 2 | C37: TOLPOS SaaS | E37: =+H18 -> 0.045316122 | G37: =SUM(J37:AS37) -> 1.8423755e+08 | H37: 1 | I37: AR$ | J37: =J18 -> 3497853.2 | K37: =K18 -> 2215231.6 | L37: =L18 -> 1647465.3 | M37: =M18 -> 1467847.5 | N37: =N18 -> 1336633.8 | O37: =O18 -> 1313581.3 | P37: =P18 -> 2085793.2 | Q37: =Q18 -> 1771809 | ... AS37: =AS18 -> 0
C38: Andesmar - TOLPOS | G38: =SUM(J38:AS38) -> 1.8423755e+08 | H38: =G38/G37 -> 1 | I38: AR$ | J38: =J403 -> 3497853.2 | K38: =K403 -> 2215231.6 | L38: =L403 -> 1647465.3 | M38: =M403 -> 1467847.5 | N38: =N403 -> 1336633.8 | O38: =O403 -> 1313581.3 | P38: =P403 -> 2085793.2 | Q38: =Q403 -> 1771809 | ... AG38: =AG403 -> 11404994 | AH38: 12139961 | AI38: 10742831 | AJ38: 9151657.9 | AK38: 9482688.2 | AL38: 8088755.3 | AM38: 12239633 | AN38: 1292904 | AO38: 864342.59 | AP38: 763085.58
C39: TOLPOS SaaS sin Andesmar | G39: =SUM(J39:AS39) -> 0 | H39: =H37-H38 -> 0 | I39: AR$ | J39: =J37-J38 -> 0 | K39: =K37-K38 -> 0 | L39: =L37-L38 -> 0 | M39: =M37-M38 -> 0 | N39: =N37-N38 -> 0 | O39: =O37-O38 -> 0 | P39: =P37-P38 -> 0 | Q39: =Q37-Q38 -> 0 | ... AS39: =AS37-AS38 -> 0
C40: Incidencia Andesmar | G40: =+G38/G37 -> 1 | I40: % | J40: =+J38/J37 -> 1 | K40: =+K38/K37 -> 1 | L40: =+L38/L37 -> 1 | M40: =+M38/M37 -> 1 | N40: =+N38/N37 -> 1 | O40: =+O38/O37 -> 1 | P40: =+P38/P37 -> 1 | Q40: =+Q38/Q37 -> 1 | ... AP40: =+AP38/AP37 -> 1
B42: 3 | C42: Plataforma UNIBUS | E42: =+H19 -> 0.29976844 | G42: =SUM(J42:AS42) -> 1.2187407e+09 | H42: 1 | I42: AR$ | J42: =J19 -> 20667399 | K42: =K19 -> 13088907 | L42: =L19 -> 9734205.7 | M42: =M19 -> 8672916.4 | N42: =N19 -> 7897628.2 | O42: =O19 -> 7761420 | P42: =P19 -> 12324108 | Q42: =Q19 -> 10468902 | ... AS42: =AS19 -> 54400307
C43: Andesmar - UNIBUS | G43: =SUM(J43:AS43) -> 1.8178694e+08 | H43: =G43/G42 -> 0.14915966 | I43: AR$ | J43: =J149 -> 1777320.1 | K43: =K149 -> 1125597.8 | L43: =L149 -> 837105.83 | M43: =M149 -> 745838.86 | N43: =N149 -> 679166.93 | O43: =O149 -> 667453.53 | P43: =P149 -> 1059827.8 | Q43: =Q149 -> 900287.01 | ... AG43: =AG149 -> 4080690.2 | AH43: 18283190 | AI43: 16620067 | AJ43: 14397423 | AK43: 14206990 | AL43: 7070575.1 | AM43: 1430912.8 | AN43: 6011628.9 | AO43: 5167917.3 | AP43: 6051290.8 | AQ43: 9774406.6 | AR43: 9031788.9 | AS43: 13038527
C44: Plataforma UNIBUS sin Andesmar | G44: =SUM(J44:AS44) -> 1.0369538e+09 | H44: =H42-H43 -> 0.85084034 | I44: AR$ | J44: =J42-J43 -> 18890078 | K44: =K42-K43 -> 11963309 | L44: =L42-L43 -> 8897099.9 | M44: =M42-M43 -> 7927077.6 | N44: =N42-N43 -> 7218461.3 | O44: =O42-O43 -> 7093966.5 | P44: =P42-P43 -> 11264280 | Q44: =Q42-Q43 -> 9568615.1 | ... AS44: =AS42-AS43 -> 41361780
C45: Incidencia Andesmar | G45: =+G43/G42 -> 0.14915966 | I45: % | J45: =+J43/J42 -> 0.085996316 | K45: =+K43/K42 -> 0.085996316 | L45: =+L43/L42 -> 0.085996316 | M45: =+M43/M42 -> 0.085996316 | N45: =+N43/N42 -> 0.085996316 | O45: =+O43/O42 -> 0.085996316 | P45: =+P43/P42 -> 0.085996316 | Q45: =+Q43/Q42 -> 0.085996316 | ... AS45: =+AS43/AS42 -> 0.23967745
C49: RATIOS DE CRECIMIENTO
B51: 1 | C51: =+C17 -> TOLWEB SaaS | D51: Crecimiento Mensual | I51: % Mes | J51: 0 | K51: =+K17/J17-1 -> -0.36668824 | L51: =+L17/K17-1 -> -0.25630109 | M51: =+M17/L17-1 -> -0.10902679 | N51: =+N17/M17-1 -> -0.089391871 | O51: =+O17/N17-1 -> -0.017246717 | P51: =+P17/O17-1 -> 0.58786761 | Q51: =+Q17/P17-1 -> -0.15053467 | R51: =+R17/Q17-1 -> 0.37866357 | ... AS51: =+AS17/AR17-1 -> 0.4256658
D52: Crecimiento Annual | I52: % Año | J52: 0 | K52: =+J52 -> 0 | L52: =+K52 -> 0 | M52: =+L52 -> 0 | N52: =+M52 -> 0 | O52: =+N52 -> 0 | P52: =+O52 -> 0 | Q52: =+P52 -> 0 | R52: =+Q52 -> 0 | ... U52: =+T52 -> 0 | V52: =SUM(V17:AG17)/SUM(J17:U17) -> 2.6186259 | W52: =SUM(W17:AH17)/SUM(K17:V17) -> 3.0638863 | X52: =SUM(X17:AI17)/SUM(L17:W17) -> 3.2495942 | Y52: =SUM(Y17:AJ17)/SUM(M17:X17) -> 3.21487 | Z52: =SUM(Z17:AK17)/SUM(N17:Y17) -> 3.3449704 | AA52: =SUM(AA17:AL17)/SUM(O17:Z17) -> 3.3267737 | AB52: =SUM(AB17:AM17)/SUM(P17:AA17) -> 3.2745774 | AC52: =SUM(AC17:AN17)/SUM(Q17:AB17) -> 3.2237917 | ... AS52: =SUM(AS17:BD17)/SUM(AG17:AR17) -> 0.11868825
B55: 2 | C55: =+C37 -> TOLPOS SaaS | D55: Crecimiento Mensual | I55: % Mes | J55: 0 | K55: =+K18/J18-1 -> -0.36668824 | L55: =+L18/K18-1 -> -0.25630109 | M55: =+M18/L18-1 -> -0.10902679 | N55: =+N18/M18-1 -> -0.089391871 | O55: =+O18/N18-1 -> -0.017246717 | P55: =+P18/O18-1 -> 0.58786761 | Q55: =+Q18/P18-1 -> -0.15053467 | R55: =+R18/Q18-1 -> 0.37866357 | ... AQ55: =+AQ18/AP18-1 -> -1
D56: Crecimiento Annual | I56: % Año | J56: 0 | K56: =+J56 -> 0 | L56: =+K56 -> 0 | M56: =+L56 -> 0 | N56: =+M56 -> 0 | O56: =+N56 -> 0 | P56: =+O56 -> 0 | Q56: =+P56 -> 0 | R56: =+Q56 -> 0 | ... U56: =+T56 -> 0 | V56: =SUM(V18:AG18)/SUM(J18:U18) -> 2.6188001 | W56: =SUM(W18:AH18)/SUM(K18:V18) -> 2.5378702 | X56: =SUM(X18:AI18)/SUM(L18:W18) -> 2.4181653 | Y56: =SUM(Y18:AJ18)/SUM(M18:X18) -> 2.2386981 | Z56: =SUM(Z18:AK18)/SUM(N18:Y18) -> 2.161035 | AA56: =SUM(AA18:AL18)/SUM(O18:Z18) -> 2.019761 | AB56: =SUM(AB18:AM18)/SUM(P18:AA18) -> 1.9409681 | AC56: =SUM(AC18:AN18)/SUM(Q18:AB18) -> 1.650241 | ... AS56: =SUM(AS18:BD18)/SUM(AG18:AR18) -> 0
B59: 3 | C59: =+C42 -> Plataforma UNIBUS | D59: Crecimiento Mensual | I59: % Mes | J59: 0 | K59: =+K19/J19-1 -> -0.36668824 | L59: =+L19/K19-1 -> -0.25630109 | M59: =+M19/L19-1 -> -0.10902679 | N59: =+N19/M19-1 -> -0.089391871 | O59: =+O19/N19-1 -> -0.017246717 | P59: =+P19/O19-1 -> 0.58786761 | Q59: =+Q19/P19-1 -> -0.15053467 | R59: =+R19/Q19-1 -> 0.37866357 | ... AS59: =+AS19/AR19-1 -> 0.031471977
D60: Crecimiento Annual | I60: % Año | J60: 0 | K60: =+J60 -> 0 | L60: =+K60 -> 0 | M60: =+L60 -> 0 | N60: =+M60 -> 0 | O60: =+N60 -> 0 | P60: =+O60 -> 0 | Q60: =+P60 -> 0 | R60: =+Q60 -> 0 | ... U60: =+T60 -> 0 | V60: =SUM(V19:AG19)/SUM(J19:U19) -> 2.6185964 | W60: =SUM(W19:AH19)/SUM(K19:V19) -> 1.9918957 | X60: =SUM(X19:AI19)/SUM(L19:W19) -> 1.7373108 | Y60: =SUM(Y19:AJ19)/SUM(M19:X19) -> 1.5651598 | Z60: =SUM(Z19:AK19)/SUM(N19:Y19) -> 1.4902771 | AA60: =SUM(AA19:AL19)/SUM(O19:Z19) -> 1.4610677 | AB60: =SUM(AB19:AM19)/SUM(P19:AA19) -> 1.3602723 | AC60: =SUM(AC19:AN19)/SUM(Q19:AB19) -> 1.2795936 | ... AS60: =SUM(AS19:BD19)/SUM(AG19:AR19) -> 0.10752702
B63: T | C63: TOTAL | D63: Crecimiento Mensual | I63: % Mes | J63: 0 | K63: =+K20/J20-1 -> -0.36668824 | L63: =+L20/K20-1 -> -0.25630109 | M63: =+M20/L20-1 -> -0.10902679 | N63: =+N20/M20-1 -> -0.089391871 | O63: =+O20/N20-1 -> -0.017246717 | P63: =+P20/O20-1 -> 0.58786761 | Q63: =+Q20/P20-1 -> -0.15053467 | R63: =+R20/Q20-1 -> 0.37866357 | ... AS63: =+AS20/AR20-1 -> 0.31549225
D64: Crecimiento Annual | I64: % Año | J64: 0 | K64: =+J64 -> 0 | L64: =+K64 -> 0 | M64: =+L64 -> 0 | N64: =+M64 -> 0 | O64: =+N64 -> 0 | P64: =+O64 -> 0 | Q64: =+P64 -> 0 | R64: =+Q64 -> 0 | ... U64: =+T64 -> 0 | V64: =SUM(V20:AG20)/SUM(J20:U20) -> 2.6186259 | W64: =SUM(W20:AH20)/SUM(K20:V20) -> 2.586213 | X64: =SUM(X20:AI20)/SUM(L20:W20) -> 2.5518965 | Y64: =SUM(Y20:AJ20)/SUM(M20:X20) -> 2.4410868 | Z64: =SUM(Z20:AK20)/SUM(N20:Y20) -> 2.4553463 | AA64: =SUM(AA20:AL20)/SUM(O20:Z20) -> 2.417403 | AB64: =SUM(AB20:AM20)/SUM(P20:AA20) -> 2.3389772 | AC64: =SUM(AC20:AN20)/SUM(Q20:AB20) -> 2.2665729 | ... AS64: =SUM(AS20:BD20)/SUM(AG20:AR20) -> 0.11205814
...

Sheet Engine
A2: VAL | B2: =+'Valuation Dashboard'!D10 -> 6.6935852 | C2: M USD | D2: 1 | H2: ANDESMAR
B3: =+B2*D3 -> 4.6855096 | C3: M USD | D3: 0.7
O6: =+YEAR(O8) -> 2023 | P6: =+YEAR(P8) -> 2023 | Q6: =+YEAR(Q8) -> 2023 | R6: =+YEAR(R8) -> 2023 | S6: =+YEAR(S8) -> 2023 | T6: =+YEAR(T8) -> 2023 | U6: =+YEAR(U8) -> 2023 | V6: =+YEAR(V8) -> 2023 | ... AX6: =+YEAR(AX8) -> 2025
N7: VENTAS HISTORICAS | O7: Q1 | P7: =+O7 -> Q1 | Q7: =+P7 -> Q1 | R7: Q2 | S7: =+R7 -> Q2 | T7: =+S7 -> Q2 | U7: Q3 | V7: =+U7 -> Q3 | W7: =+V7 -> Q3 | X7: Q4 | Y7: =+X7 -> Q4 | Z7: =+Y7 -> Q4 | AA7: Q1 | AB7: =+AA7 -> Q1 | AC7: =+AB7 -> Q1 | AD7: Q2 | AE7: =+AD7 -> Q2 | AF7: =+AE7 -> Q2 | AG7: Q3 | AH7: =+AG7 -> Q3 | AI7: =+AH7 -> Q3 | AJ7: Q4 | AK7: =+AJ7 -> Q4 | AL7: =+AK7 -> Q4 | AM7: Q1 | AN7: =+AM7 -> Q1 | AO7: =+AN7 -> Q1 | AP7: Q2 | AQ7: =+AP7 -> Q2 | AR7: =+AQ7 -> Q2 | AS7: Q3 | AT7: =+AS7 -> Q3 | AU7: =+AT7 -> Q3 | AV7: Q4 | AW7: =+AV7 -> Q4 | AX7: =+AW7 -> Q4
O8: =+Timeline!J5 -> 44957 | P8: =+Timeline!K5 -> 44985 | Q8: =+Timeline!L5 -> 45016 | R8: =+Timeline!M5 -> 45046 | S8: =+Timeline!N5 -> 45077 | T8: =+Timeline!O5 -> 45107 | U8: =+Timeline!P5 -> 45138 | V8: =+Timeline!Q5 -> 45169 | ... AX8: =+Timeline!AS5 -> 46022
N9: TOLWEB SaaS | O9: =+Timeline!J679 -> 79567.891 | P9: =+Timeline!K679 -> 51331.919 | Q9: =+Timeline!L679 -> 36426.997 | R9: =+Timeline!M679 -> 27254.28 | S9: =+Timeline!N679 -> 23703.692 | T9: =+Timeline!O679 -> 23153.128 | U9: =+Timeline!P679 -> 32954.004 | V9: =+Timeline!Q679 -> 21090.83 | ... AX9: =+Timeline!AS679 -> 133220.38
M10: FALSE | N10: Andesmar - TOLWEB | O10: =+Timeline!J680 -> 18377.078 | P10: =+Timeline!K680 -> 11855.67 | Q10: =+Timeline!L680 -> 8413.2146 | R10: =+Timeline!M680 -> 6294.6749 | S10: =+Timeline!N680 -> 5474.6279 | T10: =+Timeline!O680 -> 5347.4689 | U10: =+Timeline!P680 -> 7611.0888 | V10: =+Timeline!Q680 -> 4871.1587 | ... AX10: =+Timeline!AS680 -> 0
N11: Total TOLWEB | O11: =+O9-(O10*(1-$M$10)) -> 61190.814 | P11: =+P9-(P10*(1-$M$10)) -> 39476.249 | Q11: =+Q9-(Q10*(1-$M$10)) -> 28013.782 | R11: =+R9-(R10*(1-$M$10)) -> 20959.605 | S11: =+S9-(S10*(1-$M$10)) -> 18229.065 | T11: =+T9-(T10*(1-$M$10)) -> 17805.659 | U11: =+U9-(U10*(1-$M$10)) -> 25342.915 | V11: =+V9-(V10*(1-$M$10)) -> 16219.672 | ... AX11: =+AX9-(AX10*(1-$M$10)) -> 133220.38
N13: TOLPOS SaaS | O13: =+Timeline!J684 -> 9156.6837 | P13: =+Timeline!K684 -> 5907.2842 | Q13: =+Timeline!L684 -> 4192.0237 | R13: =+Timeline!M684 -> 3136.4262 | S13: =+Timeline!N684 -> 2727.8241 | T13: =+Timeline!O684 -> 2664.4651 | U13: =+Timeline!P684 -> 3792.3512 | V13: =+Timeline!Q684 -> 2427.1356 | ... AX13: =+Timeline!AS684 -> 0
M14: =+M10 -> FALSE | N14: Andesmar - TOLPOS | O14: =+Timeline!J685 -> 9156.6837 | P14: =+Timeline!K685 -> 5907.2842 | Q14: =+Timeline!L685 -> 4192.0237 | R14: =+Timeline!M685 -> 3136.4262 | S14: =+Timeline!N685 -> 2727.8241 | T14: =+Timeline!O685 -> 2664.4651 | U14: =+Timeline!P685 -> 3792.3512 | V14: =+Timeline!Q685 -> 2427.1356 | ... AX14: =+Timeline!AS685 -> 0
N15: Total TOLPOS | O15: =+O13-(O14*(1-$M$14)) -> 0 | P15: =+P13-(P14*(1-$M$14)) -> 0 | Q15: =+Q13-(Q14*(1-$M$14)) -> 0 | R15: =+R13-(R14*(1-$M$14)) -> 0 | S15: =+S13-(S14*(1-$M$14)) -> 0 | T15: =+T13-(T14*(1-$M$14)) -> 0 | U15: =+U13-(U14*(1-$M$14)) -> 0 | V15: =+V13-(V14*(1-$M$14)) -> 0 | ... AX15: =+AX13-(AX14*(1-$M$14)) -> 0
N17: Plataforma UNIBUS | O17: =+Timeline!J689 -> 54103.138 | P17: =+Timeline!K689 -> 34903.751 | Q17: =+Timeline!L689 -> 24768.971 | R17: =+Timeline!M689 -> 18531.873 | S17: =+Timeline!N689 -> 16117.609 | T17: =+Timeline!O689 -> 15743.246 | U17: =+Timeline!P689 -> 22407.468 | V17: =+Timeline!Q689 -> 14340.962 | ... AX17: =+Timeline!AS689 -> 37388.527
M18: TRUE | N18: Andesmar - UNIBUS | O18: =+Timeline!J690 -> 4652.6705 | P18: =+Timeline!K690 -> 3001.594 | Q18: =+Timeline!L690 -> 2130.0403 | R18: =+Timeline!M690 -> 1593.6728 | S18: =+Timeline!N690 -> 1386.055 | T18: =+Timeline!O690 -> 1353.8611 | U18: =+Timeline!P690 -> 1926.9597 | V18: =+Timeline!Q690 -> 1233.2699 | ... AX18: =+Timeline!AS690 -> 8961.187
N19: Total UNIBUS | O19: =+O17-(O18*(1-$M$18)) -> 54103.138 | P19: =+P17-(P18*(1-$M$18)) -> 34903.751 | Q19: =+Q17-(Q18*(1-$M$18)) -> 24768.971 | R19: =+R17-(R18*(1-$M$18)) -> 18531.873 | S19: =+S17-(S18*(1-$M$18)) -> 16117.609 | T19: =+T17-(T18*(1-$M$18)) -> 15743.246 | U19: =+U17-(U18*(1-$M$18)) -> 22407.468 | V19: =+V17-(V18*(1-$M$18)) -> 14340.962 | ... AX19: =+AX17-(AX18*(1-$M$18)) -> 37388.527
N21: Ventas Totales | O21: =+O19+O15+O11 -> 115293.95 | P21: =+P19+P15+P11 -> 74380 | Q21: =+Q19+Q15+Q11 -> 52782.753 | R21: =+R19+R15+R11 -> 39491.477 | S21: =+S19+S15+S11 -> 34346.673 | T21: =+T19+T15+T11 -> 33548.904 | U21: =+U19+U15+U11 -> 47750.383 | V21: =+V19+V15+V11 -> 30560.633 | ... AX21: =+AX19+AX15+AX11 -> 170608.91
N31: VENTAS HISTORICAS | O31: =+Timeline!J667 -> 142827.71
O32: =+O8 -> 44957 | P32: =+P8 -> 44985 | Q32: =+Q8 -> 45016 | R32: =+R8 -> 45046 | S32: =+S8 -> 45077 | T32: =+T8 -> 45107 | U32: =+U8 -> 45138 | V32: =+V8 -> 45169 | ... AX32: =+AX8 -> 46022
N33: Ventas totales | O33: =+O21 -> 115293.95 | P33: =+P21 -> 74380 | Q33: =+Q21 -> 52782.753 | R33: =+R21 -> 39491.477 | S33: =+S21 -> 34346.673 | T33: =+T21 -> 33548.904 | U33: =+U21 -> 47750.383 | V33: =+V21 -> 30560.633 | ... AX33: =+AX21 -> 170608.91
N34: Ventas SIN Andesmar | O34: =+Timeline!J671 -> 110641.28 | P34: =+Timeline!K671 -> 71378.406 | Q34: =+Timeline!L671 -> 50652.713 | R34: =+Timeline!M671 -> 37897.805 | S34: =+Timeline!N671 -> 32960.618 | T34: =+Timeline!O671 -> 32195.043 | U34: =+Timeline!P671 -> 45823.423 | V34: =+Timeline!Q671 -> 29327.363 | ... AX34: =+Timeline!AS671 -> 161647.72
N51: VENTAS HISTORICAS | O51: =+O33 -> 115293.95 | P51: =+P33 -> 74380 | Q51: =+Q33 -> 52782.753 | R51: =+R33 -> 39491.477 | S51: =+S33 -> 34346.673 | T51: =+T33 -> 33548.904 | U51: =+U33 -> 47750.383 | V51: =+V33 -> 30560.633 | ... AX51: =+AX33 -> 170608.91
N53: CORRELACION COSTOS SOBRE VENTAS TOTALES
O55: =+O32 -> 44957 | P55: =+P32 -> 44985 | Q55: =+Q32 -> 45016 | R55: =+R32 -> 45046 | S55: =+S32 -> 45077 | T55: =+T32 -> 45107 | U55: =+U32 -> 45138 | V55: =+V32 -> 45169 | ... AX55: =+AX32 -> 46022
N56: =+Timeline!C735 -> OPERACIONES | O56: =+Timeline!J739 -> 0.075101017 | P56: =+Timeline!K739 -> 0.11717327 | Q56: =+Timeline!L739 -> 0.11446752 | R56: =+Timeline!M739 -> 0.083133023 | S56: =+Timeline!N739 -> 0.10071376 | T56: =+Timeline!O739 -> 0.10172088 | U56: =+Timeline!P739 -> 0.12609303 | V56: =+Timeline!Q739 -> 0.10068697 | ... AO56: =+Timeline!AJ739 -> 0.21183623 | AP56: =+CHOOSE($AO$61,AP63,AP68,AP73) -> 0.14 | AQ56: =+CHOOSE($AO$61,AQ63,AQ68,AQ73) -> 0.14 | AR56: =+CHOOSE($AO$61,AR63,AR68,AR73) -> 0.09 | AS56: =+CHOOSE($AO$61,AS63,AS68,AS73) -> 0.09 | AT56: =+CHOOSE($AO$61,AT63,AT68,AT73) -> 0.09 | AU56: =+CHOOSE($AO$61,AU63,AU68,AU73) -> 0.08 | AV56: =+CHOOSE($AO$61,AV63,AV68,AV73) -> 0.08 | AW56: =+CHOOSE($AO$61,AW63,AW68,AW73) -> 0.08 | AX56: =+CHOOSE($AO$61,AX63,AX68,AX73) -> 0.1
N57: =+Timeline!C741 -> INFRAESTRUCTURA | O57: =+Timeline!J745 -> 0.058523589 | P57: =+Timeline!K745 -> 0.13161717 | Q57: =+Timeline!L745 -> 0.18330572 | R57: =+Timeline!M745 -> 0.18379562 | S57: =+Timeline!N745 -> 0.22849083 | T57: =+Timeline!O745 -> 0.25064117 | U57: =+Timeline!P745 -> 0.19507916 | V57: =+Timeline!Q745 -> 0.23457804 | ... AO57: =+Timeline!AJ745 -> 0.19733822 | AP57: =+CHOOSE($AO$61,AP64,AP69,AP74) -> 0.28 | AQ57: =+CHOOSE($AO$61,AQ64,AQ69,AQ74) -> 0.28 | AR57: =+CHOOSE($AO$61,AR64,AR69,AR74) -> 0.18 | AS57: =+CHOOSE($AO$61,AS64,AS69,AS74) -> 0.18 | AT57: =+CHOOSE($AO$61,AT64,AT69,AT74) -> 0.18 | AU57: =+CHOOSE($AO$61,AU64,AU69,AU74) -> 0.2 | AV57: =+CHOOSE($AO$61,AV64,AV69,AV74) -> 0.2 | AW57: =+CHOOSE($AO$61,AW64,AW69,AW74) -> 0.2 | AX57: =+CHOOSE($AO$61,AX64,AX69,AX74) -> 0.22
N58: =+Timeline!C747 -> PERSONAL | O58: =+Timeline!J751 -> 0.14712334 | P58: =+Timeline!K751 -> 0.2233149 | Q58: =+Timeline!L751 -> 0.35124486 | R58: =+Timeline!M751 -> 0.42719317 | S58: =+Timeline!N751 -> 0.52080671 | T58: =+Timeline!O751 -> 0.77602276 | U58: =+Timeline!P751 -> 0.36093712 | V58: =+Timeline!Q751 -> 0.46792428 | ... AO58: =+Timeline!AJ751 -> 0.37090348 | AP58: =+CHOOSE($AO$61,AP65,AP70,AP75) -> 0.52 | AQ58: =+CHOOSE($AO$61,AQ65,AQ70,AQ75) -> 0.52 | AR58: =+CHOOSE($AO$61,AR65,AR70,AR75) -> 0.41 | AS58: =+CHOOSE($AO$61,AS65,AS70,AS75) -> 0.41 | AT58: =+CHOOSE($AO$61,AT65,AT70,AT75) -> 0.41 | AU58: =+CHOOSE($AO$61,AU65,AU70,AU75) -> 0.5 | AV58: =+CHOOSE($AO$61,AV65,AV70,AV75) -> 0.5 | AW58: =+CHOOSE($AO$61,AW65,AW70,AW75) -> 0.5 | AX58: =+CHOOSE($AO$61,AX65,AX70,AX75) -> 0.45
N59: =+Timeline!C753 -> TOTAL | O59: =+Timeline!J757 -> 0.28074795 | P59: =+Timeline!K757 -> 0.47210533 | Q59: =+Timeline!L757 -> 0.6490181 | R59: =+Timeline!M757 -> 0.69412181 | S59: =+Timeline!N757 -> 0.8500113 | T59: =+Timeline!O757 -> 1.1283848 | U59: =+Timeline!P757 -> 0.6821093 | V59: =+Timeline!Q757 -> 0.80318929 | ... AO59: =+Timeline!AJ757 -> 0.78007793 | AP59: =+CHOOSE($AO$61,AP66,AP71,AP76) -> 0.94 | AQ59: =+CHOOSE($AO$61,AQ66,AQ71,AQ76) -> 0.94 | AR59: =+CHOOSE($AO$61,AR66,AR71,AR76) -> 0.68 | AS59: =+CHOOSE($AO$61,AS66,AS71,AS76) -> 0.68 | AT59: =+CHOOSE($AO$61,AT66,AT71,AT76) -> 0.68 | AU59: =+CHOOSE($AO$61,AU66,AU71,AU76) -> 0.78 | AV59: =+CHOOSE($AO$61,AV66,AV71,AV76) -> 0.78 | AW59: =+CHOOSE($AO$61,AW66,AW71,AW76) -> 0.78 | AX59: =+CHOOSE($AO$61,AX66,AX71,AX76) -> 0.77
AO61: 1
AO63: IA | AP63: 0.14 | AQ63: 0.14 | AR63: 0.09 | AS63: 0.09 | AT63: 0.09 | AU63: 0.08 | AV63: 0.08 | AW63: 0.08 | AX63: 0.1
AP64: 0.28 | AQ64: 0.28 | AR64: 0.18 | AS64: 0.18 | AT64: 0.18 | AU64: 0.2 | AV64: 0.2 | AW64: 0.2 | AX64: 0.22
AP65: 0.52 | AQ65: 0.52 | AR65: 0.41 | AS65: 0.41 | AT65: 0.41 | AU65: 0.5 | AV65: 0.5 | AW65: 0.5 | AX65: 0.45
AP66: 0.94 | AQ66: 0.94 | AR66: 0.68 | AS66: 0.68 | AT66: 0.68 | AU66: 0.78 | AV66: 0.78 | AW66: 0.78 | AX66: 0.77
AO68: 2024 | AP68: =+AD56 -> 0.13229954 | AQ68: =+AE56 -> 0.11906064 | AR68: =+AF56 -> 0.080045379 | AS68: =+AG56 -> 0.10985019 | AT68: =+AH56 -> 0.10543363 | AU68: =+AI56 -> 0.095015276 | AV68: =+AJ56 -> 0.1052246 | AW68: =+AK56 -> 0.089020995 | AX68: =+AL56 -> 0.081760828
AP69: =+AD57 -> 0.31557251 | AQ69: =+AE57 -> 0.24849657 | AR69: =+AF57 -> 0.22506221 | AS69: =+AG57 -> 0.24224858 | AT69: =+AH57 -> 0.35466665 | AU69: =+AI57 -> 0.2050577 | AV69: =+AJ57 -> 0.17729756 | AW69: =+AK57 -> 0.14431648 | AX69: =+AL57 -> 0.094368514
AP70: =+AD58 -> 0.54945953 | AQ70: =+AE58 -> 0.5587482 | AR70: =+AF58 -> 0.66037274 | AS70: =+AG58 -> 0.40150863 | AT70: =+AH58 -> 0.50155842 | AU70: =+AI58 -> 0.38915707 | AV70: =+AJ58 -> 0.34029349 | AW70: =+AK58 -> 0.27759434 | AX70: =+AL58 -> 0.28461054
AP71: =+AD59 -> 0.99733158 | AQ71: =+AE59 -> 0.92630541 | AR71: =+AF59 -> 0.96548033 | AS71: =+AG59 -> 0.75360741 | AT71: =+AH59 -> 0.9616587 | AU71: =+AI59 -> 0.68923004 | AV71: =+AJ59 -> 0.62281565 | AW71: =+AK59 -> 0.51093182 | AX71: =+AL59 -> 0.46073989
AO73: Avg 2023/24 | AP73: =+AVERAGE(R56,AD56) -> 0.10771628 | AQ73: =+AVERAGE(S56,AE56) -> 0.1098872 | AR73: =+AVERAGE(T56,AF56) -> 0.09088313 | AS73: =+AVERAGE(U56,AG56) -> 0.11797161 | AT73: =+AVERAGE(V56,AH56) -> 0.1030603 | AU73: =+AVERAGE(W56,AI56) -> 0.082272095 | AV73: =+AVERAGE(X56,AJ56) -> 0.089882211 | AW73: =+AVERAGE(Y56,AK56) -> 0.078597888 | AX73: =+AVERAGE(Z56,AL56) -> 0.07497657
AP74: =+AVERAGE(R57,AD57) -> 0.24968406 | AQ74: =+AVERAGE(S57,AE57) -> 0.2384937 | AR74: =+AVERAGE(T57,AF57) -> 0.23785169 | AS74: =+AVERAGE(U57,AG57) -> 0.21866387 | AT74: =+AVERAGE(V57,AH57) -> 0.29462234 | AU74: =+AVERAGE(W57,AI57) -> 0.19914943 | AV74: =+AVERAGE(X57,AJ57) -> 0.16354791 | AW74: =+AVERAGE(Y57,AK57) -> 0.13330822 | AX74: =+AVERAGE(Z57,AL57) -> 0.092176881
AP75: =+AVERAGE(R58,AD58) -> 0.48832635 | AQ75: =+AVERAGE(S58,AE58) -> 0.53977745 | AR75: =+AVERAGE(T58,AF58) -> 0.71819775 | AS75: =+AVERAGE(U58,AG58) -> 0.38122288 | AT75: =+AVERAGE(V58,AH58) -> 0.48474135 | AU75: =+AVERAGE(W58,AI58) -> 0.37924812 | AV75: =+AVERAGE(X58,AJ58) -> 0.34786755 | AW75: =+AVERAGE(Y58,AK58) -> 0.28392576 | AX75: =+AVERAGE(Z58,AL58) -> 0.26838338
AP76: =+AVERAGE(R59,AD59) -> 0.84572669 | AQ76: =+AVERAGE(S59,AE59) -> 0.88815835 | AR76: =+AVERAGE(T59,AF59) -> 1.0469326 | AS76: =+AVERAGE(U59,AG59) -> 0.71785835 | AT76: =+AVERAGE(V59,AH59) -> 0.882424 | AU76: =+AVERAGE(W59,AI59) -> 0.66066964 | AV76: =+AVERAGE(X59,AJ59) -> 0.60129767 | AW76: =+AVERAGE(Y59,AK59) -> 0.49583186 | AX76: =+AVERAGE(Z59,AL59) -> 0.43553683
N79: COSTOS
...

Sheet WACC
B1: Componente | C1: Valor | D1: Explicación
B2: Rf (Tasa libre de riesgo) | C2: 0.044 | D2: Tasa libre de riesgo, basada en bonos del Tesoro de EE.UU. a 10 años. | E2: NOTA
B3: Riesgo Pais | C3: 0.063 | E3: NOTA
B4: Prima de mercado (Rm - Rf) | C4: 0.042 | D4: Prima que el mercado exige sobre la tasa libre de riesgo, incluye riesgo país.
B5: Beta (β) | C5: 1.1 | D5: Sensibilidad de la empresa respecto al mercado, estimada por comparables del sector. Despegar, Booking.
B6: Prima Tamaño | C6: 0.0245
B7: Ke (Costo del Equity) | C7: =+C2+C5*C4+C3+C6 -> 0.1777 | D7: Costo del equity, calculado con CAPM: Rf + β*(Rm - Rf).
B8: Kd (Costo de la deuda) | C8: 0.07 | D8: Costo nominal estimado de la deuda en USD.
B9: Tasa Impositiva (T) | C9: 0.35 | D9: Tasa de impuesto corporativo aplicada a la deducción de intereses.
B10: E/V (Proporción Equity) | C10: 0.75 | D10: Proporción del capital financiado por equity (patrimonio).
B11: D/V (Proporción Deuda) | C11: 0.76 | D11: Proporción del capital financiado por deuda.
B13: Equity Cost (Ke) | C13: =+C7 -> 0.1777
B14: Debt Cost (Kd) | C14: =+C8*(1-C9) -> 0.0455
B16: E/V (Proporción Equity) | C16: 0.75
B17: D/V (Proporción Deuda) | C17: 0.62
B19: WACC | C19: =+(C16*C13+C17*C14) -> 0.161485

Sheet Benchmark Projections
A1: Quarter | B1: SaaS Tourism (USD B) | C1: AI in Tourism SaaS (USD B) | D1: OTAs (USD B) | F1: Quarter | G1: 2023-Q%q | H1: 2023-Q%q | I1: 2023-Q%q | J1: 2023-Q%q | K1: 2024-Q%q | L1: 2024-Q%q | M1: 2024-Q%q | N1: 2024-Q%q | O1: 2025-Q%q | P1: 2025-Q%q | Q1: 2025-Q%q | R1: 2025-Q%q | S1: 2026-Q%q | T1: 2026-Q%q | U1: 2026-Q%q | V1: 2026-Q%q | W1: 2027-Q%q | X1: 2027-Q%q | Y1: 2027-Q%q | Z1: 2027-Q%q | AA1: 2028-Q%q | AB1: 2028-Q%q | AC1: 2028-Q%q | AD1: 2028-Q%q | AE1: 2029-Q%q | AF1: 2029-Q%q | AG1: 2029-Q%q | AH1: 2029-Q%q | AI1: 2030-Q%q | AJ1: 2030-Q%q | AK1: 2030-Q%q | AL1: 2030-Q%q
A2: 2023-Q%q | B2: 10.65 | C2: 0.69 | D2: 8.43 | F2: SaaS Tourism (USD B) | G2: 10.65 | H2: 10.969966 | I2: 11.299545 | J2: 11.639025 | K2: 11.988705 | L2: 12.348891 | M2: 12.719897 | N2: 13.102051 | O2: 13.495685 | P2: 13.901146 | Q2: 14.318788 | R2: 14.748978 | S2: 15.192093 | T2: 15.64852 | U2: 16.11866 | V2: 16.602925 | W2: 17.101739 | X2: 17.615539 | Y2: 18.144776 | Z2: 18.689913 | AA2: 19.251427 | AB2: 19.829812 | AC2: 20.425574 | AD2: 21.039235 | AE2: 21.671332 | AF2: 22.32242 | AG2: 22.993069 | AH2: 23.683866 | AI2: 24.395418 | AJ2: 25.128348 | AK2: 25.883297 | AL2: 26.660928
A3: 2023-Q%q | B3: 10.969966 | C3: 0.72249399 | D3: 8.6118115 | F3: AI in Tourism SaaS (USD B) | G3: 0.69 | H3: 0.72249399 | I3: 0.75651822 | J3: 0.79214473 | K3: 0.829449 | L3: 0.86851003 | M3: 0.90941055 | N3: 0.95223718 | O3: 0.99708064 | P3: 1.0440359 | Q3: 1.0932024 | R3: 1.1446843 | S3: 1.1985906 | T3: 1.2550356 | U3: 1.3141386 | V3: 1.376025 | W3: 1.4408258 | X3: 1.5086782 | Y3: 1.579726 | Z3: 1.6541197 | AA3: 1.7320167 | AB3: 1.8135821 | AC3: 1.8989887 | AD3: 1.9884173 | AE3: 2.0820573 | AF3: 2.1801071 | AG3: 2.2827743 | AH3: 2.3902764 | AI3: 2.5028411 | AJ3: 2.6207067 | AK3: 2.744123 | AL3: 2.8733512
A4: 2023-Q%q | B4: 11.299545 | C4: 0.75651822 | D4: 8.7975441 | F4: OTAs (USD B) | G4: 8.43 | H4: 8.6118115 | I4: 8.7975441 | J4: 8.9872825 | K4: 9.181113 | L4: 9.3791239 | M4: 9.5814053 | N4: 9.7880494 | O4: 9.9991502 | P4: 10.214804 | Q4: 10.435109 | R4: 10.660165 | S4: 10.890074 | T4: 11.124943 | U4: 11.364877 | V4: 11.609985 | W4: 11.86038 | X4: 12.116175 | Y4: 12.377487 | Z4: 12.644435 | AA4: 12.91714 | AB4: 13.195726 | AC4: 13.480321 | AD4: 13.771054 | AE4: 14.068057 | AF4: 14.371466 | AG4: 14.681418 | AH4: 14.998055 | AI4: 15.321521 | AJ4: 15.651963 | AK4: 15.989532 | AL4: 16.334382
A5: 2023-Q%q | B5: 11.639025 | C5: 0.79214473 | D5: 8.9872825 | G5: 2023 | H5: 2023 | I5: 2023 | J5: 2023 | K5: 2024 | L5: 2024 | M5: 2024 | N5: 2024 | O5: 2025 | P5: 2025 | Q5: 2025 | R5: 2025 | S5: 2026 | T5: 2026 | U5: 2026 | V5: 2026 | W5: 2027 | X5: 2027 | Y5: 2027 | Z5: 2027 | AA5: 2028 | AB5: 2028 | AC5: 2028 | AD5: 2028 | AE5: 2029 | AF5: 2029 | AG5: 2029 | AH5: 2029 | AI5: 2030 | AJ5: 2030 | AK5: 2030 | AL5: 2030
A6: 2024-Q%q | B6: 11.988705 | C6: 0.829449 | D6: 9.181113 | G6: Q1 | H6: Q2 | I6: Q3 | J6: Q4 | K6: Q1 | L6: Q2 | M6: Q3 | N6: Q4 | O6: Q1 | P6: Q2 | Q6: Q3 | R6: Q4 | S6: Q1 | T6: Q2 | U6: Q3 | V6: Q4 | W6: Q1 | X6: Q2 | Y6: Q3 | Z6: Q4 | AA6: Q1 | AB6: Q2 | AC6: Q3 | AD6: Q4 | AE6: Q1 | AF6: Q2 | AG6: Q3 | AH6: Q4 | AI6: Q1 | AJ6: Q2 | AK6: Q3 | AL6: Q4
A7: 2024-Q%q | B7: 12.348891 | C7: 0.86851003 | D7: 9.3791239 | G7: 2023 Q1 | H7: 2023 Q2 | I7: 2023 Q3 | J7: 2023 Q4 | K7: 2024 Q1 | L7: 2024 Q2 | M7: 2024 Q3 | N7: 2024 Q4 | O7: 2025 Q1 | P7: 2025 Q2 | Q7: 2025 Q3 | R7: 2025 Q4 | S7: 2026 Q1 | T7: 2026 Q2 | U7: 2026 Q3 | V7: 2026 Q4 | W7: 2027 Q1 | X7: 2027 Q2 | Y7: 2027 Q3 | Z7: 2027 Q4 | AA7: 2028 Q1 | AB7: 2028 Q2 | AC7: 2028 Q3 | AD7: 2028 Q4 | AE7: 2029 Q1 | AF7: 2029 Q2 | AG7: 2029 Q3 | AH7: 2029 Q4 | AI7: 2030 Q1 | AJ7: 2030 Q2 | AK7: 2030 Q3 | AL7: 2030 Q4
A8: 2024-Q%q | B8: 12.719897 | C8: 0.90941055 | D8: 9.5814053 | F8: SaaS Tourism (USD B) | G8: 10.65 | H8: 21.619966 | I8: 32.91951 | J8: 44.558536 | K8: 56.547241 | L8: 68.896131 | M8: 81.616028 | N8: 94.718079 | O8: 108.21376 | P8: 122.11491 | Q8: 136.4337 | R8: 151.18268 | S8: 166.37477 | T8: 182.02329 | U8: 198.14195 | V8: 214.74488 | W8: 231.84661 | X8: 249.46215 | Y8: 267.60693 | Z8: 286.29684 | AA8: 305.54827 | AB8: 325.37808 | AC8: 345.80366 | AD8: 366.84289 | AE8: 388.51422 | AF8: 410.83664 | AG8: 433.82971 | AH8: 457.51358 | AI8: 481.909 | AJ8: 507.03734 | AK8: 532.92064 | AL8: 559.58157
A9: 2024-Q%q | B9: 13.102051 | C9: 0.95223718 | D9: 9.7880494 | F9: AI in Tourism SaaS (USD B) | G9: 0.69 | H9: 1.412494 | I9: 2.1690122 | J9: 2.9611569 | K9: 3.7906059 | L9: 4.659116 | M9: 5.5685265 | N9: 6.5207637 | O9: 7.5178443 | P9: 8.5618802 | Q9: 9.6550827 | R9: 10.799767 | S9: 11.998358 | T9: 13.253393 | U9: 14.567532 | V9: 15.943557 | W9: 17.384383 | X9: 18.893061 | Y9: 20.472787 | Z9: 22.126907 | AA9: 23.858923 | AB9: 25.672505 | AC9: 27.571494 | AD9: 29.559911 | AE9: 31.641969 | AF9: 33.822076 | AG9: 36.10485 | AH9: 38.495126 | AI9: 40.997967 | AJ9: 43.618674 | AK9: 46.362797 | AL9: 49.236148
A10: 2025-Q%q | B10: 13.495685 | C10: 0.99708064 | D10: 9.9991502 | F10: OTAs (USD B) | G10: 8.43 | H10: 17.041811 | I10: 25.839356 | J10: 34.826638 | K10: 44.007751 | L10: 53.386875 | M10: 62.96828 | N10: 72.75633 | O10: 82.75548 | P10: 92.970284 | Q10: 103.40539 | R10: 114.06556 | S10: 124.95563 | T10: 136.08057 | U10: 147.44545 | V10: 159.05544 | W10: 170.91582 | X10: 183.03199 | Y10: 195.40948 | Z10: 208.05391 | AA10: 220.97105 | AB10: 234.16678 | AC10: 247.6471 | AD10: 261.41816 | AE10: 275.48621 | AF10: 289.85768 | AG10: 304.5391 | AH10: 319.53715 | AI10: 334.85867 | AJ10: 350.51064 | AK10: 366.50017 | AL10: 382.83455
A11: 2025-Q%q | B11: 13.901146 | C11: 1.0440359 | D11: 10.214804
A12: 2025-Q%q | B12: 14.318788 | C12: 1.0932024 | D12: 10.435109
A13: 2025-Q%q | B13: 14.748978 | C13: 1.1446843 | D13: 10.660165
A14: 2026-Q%q | B14: 15.192093 | C14: 1.1985906 | D14: 10.890074
A15: 2026-Q%q | B15: 15.64852 | C15: 1.2550356 | D15: 11.124943
A16: 2026-Q%q | B16: 16.11866 | C16: 1.3141386 | D16: 11.364877
A17: 2026-Q%q | B17: 16.602925 | C17: 1.376025 | D17: 11.609985
A18: 2027-Q%q | B18: 17.101739 | C18: 1.4408258 | D18: 11.86038
A19: 2027-Q%q | B19: 17.615539 | C19: 1.5086782 | D19: 12.116175
A20: 2027-Q%q | B20: 18.144776 | C20: 1.579726 | D20: 12.377487
A21: 2027-Q%q | B21: 18.689913 | C21: 1.6541197 | D21: 12.644435
A22: 2028-Q%q | B22: 19.251427 | C22: 1.7320167 | D22: 12.91714
... A33: 2030-Q%q | B33: 26.660928 | C33: 2.8733512 | D33: 16.334382
G38: =+G7 -> 2023 Q1 | H38: =+H7 -> 2023 Q2 | I38: =+I7 -> 2023 Q3 | J38: =+J7 -> 2023 Q4 | K38: =+K7 -> 2024 Q1 | L38: =+L7 -> 2024 Q2 | M38: =+M7 -> 2024 Q3 | N38: =+N7 -> 2024 Q4 | ... AL38: =+AL7 -> 2030 Q4
F39: =+F8 -> SaaS Tourism (USD B) | G39: =+G2 -> 10.65 | H39: =+H2 -> 10.969966 | I39: =+I2 -> 11.299545 | J39: =+J2 -> 11.639025 | K39: =+K2 -> 11.988705 | L39: =+L2 -> 12.348891 | M39: =+M2 -> 12.719897 | N39: =+N2 -> 13.102051 | ... AL39: =+AL2 -> 26.660928
F40: =+F9 -> AI in Tourism SaaS (USD B) | G40: =+G3 -> 0.69 | H40: =+H3 -> 0.72249399 | I40: =+I3 -> 0.75651822 | J40: =+J3 -> 0.79214473 | K40: =+K3 -> 0.829449 | L40: =+L3 -> 0.86851003 | M40: =+M3 -> 0.90941055 | N40: =+N3 -> 0.95223718 | ... AL40: =+AL3 -> 2.8733512
F41: =+F10 -> OTAs (USD B) | G41: =+G4 -> 8.43 | H41: =+H4 -> 8.6118115 | I41: =+I4 -> 8.7975441 | J41: =+J4 -> 8.9872825 | K41: =+K4 -> 9.181113 | L41: =+L4 -> 9.3791239 | M41: =+M4 -> 9.5814053 | N41: =+N4 -> 9.7880494 | ... AL41: =+AL4 -> 16.334382
F44: CURVAS TRIMESTRALES
F45: =+F39 -> SaaS Tourism (USD B) | G45: 0 | H45: =+(H39-G39)/G39 -> 0.030043739 | I45: =+(I39-H39)/H39 -> 0.030043738 | J45: =+(J39-I39)/I39 -> 0.030043739 | K45: =+(K39-J39)/J39 -> 0.030043739 | L45: =+(L39-K39)/K39 -> 0.030043739 | M45: =+(M39-L39)/L39 -> 0.030043739 | N45: =+(N39-M39)/M39 -> 0.030043738 | O45: =+(O39-N39)/N39 -> 0.030043739 | ... AL45: =+(AL39-AK39)/AK39 -> 0.030043739
F46: =+F40 -> AI in Tourism SaaS (USD B) | G46: 0 | H46: =+(H40-G40)/G40 -> 0.047092742 | I46: =+(I40-H40)/H40 -> 0.047092742 | J46: =+(J40-I40)/I40 -> 0.047092742 | K46: =+(K40-J40)/J40 -> 0.047092743 | L46: =+(L40-K40)/K40 -> 0.047092742 | M46: =+(M40-L40)/L40 -> 0.047092742 | N46: =+(N40-M40)/M40 -> 0.047092742 | O46: =+(O40-N40)/N40 -> 0.047092742 | ... AL46: =+(AL40-AK40)/AK40 -> 0.047092742
F47: =+F41 -> OTAs (USD B) | G47: 0 | H47: =+(H41-G41)/G41 -> 0.021567198 | I47: =+(I41-H41)/H41 -> 0.021567198 | J47: =+(J41-I41)/I41 -> 0.021567198 | K47: =+(K41-J41)/J41 -> 0.021567198 | L47: =+(L41-K41)/K41 -> 0.021567198 | M47: =+(M41-L41)/L41 -> 0.021567198 | N47: =+(N41-M41)/M41 -> 0.021567198 | O47: =+(O41-N41)/N41 -> 0.021567198 | ... AL47: =+(AL41-AK41)/AK41 -> 0.021567198
F50: CURVAS ACUMULADAS
F51: =+F45 -> SaaS Tourism (USD B) | G51: =+G45 -> 0 | H51: =+H45+G51 -> 0.030043739 | I51: =+I45+H51 -> 0.060087477 | J51: =+J45+I51 -> 0.090131216 | K51: =+K45+J51 -> 0.12017495 | L51: =+L45+K51 -> 0.15021869 | M51: =+M45+L51 -> 0.18026243 | N51: =+N45+M51 -> 0.21030617 | O51: =+O45+N51 -> 0.24034991 | ... AL51: =+AL45+AK51 -> 0.9313559
F52: =+F46 -> AI in Tourism SaaS (USD B) | G52: =+G46 -> 0 | H52: =+H46+G52 -> 0.047092742 | I52: =+I46+H52 -> 0.094185484 | J52: =+J46+I52 -> 0.14127823 | K52: =+K46+J52 -> 0.18837097 | L52: =+L46+K52 -> 0.23546371 | M52: =+M46+L52 -> 0.28255645 | N52: =+N46+M52 -> 0.32964919 | O52: =+O46+N52 -> 0.37674194 | ... AL52: =+AL46+AK52 -> 1.459875
F53: =+F47 -> OTAs (USD B) | G53: =+G47 -> 0 | H53: =+H47+G53 -> 0.021567198 | I53: =+I47+H53 -> 0.043134396 | J53: =+J47+I53 -> 0.064701594 | K53: =+K47+J53 -> 0.086268792 | L53: =+L47+K53 -> 0.10783599 | M53: =+M47+L53 -> 0.12940319 | N53: =+N47+M53 -> 0.15097039 | O53: =+O47+N53 -> 0.17253758 | ... AL53: =+AL47+AK53 -> 0.66858314
F56: Quarter | G56: =+G38 -> 2023 Q1 | H56: =+H38 -> 2023 Q2 | I56: =+I38 -> 2023 Q3 | J56: =+J38 -> 2023 Q4 | K56: =+K38 -> 2024 Q1 | L56: =+L38 -> 2024 Q2 | M56: =+M38 -> 2024 Q3 | N56: =+N38 -> 2024 Q4 | ... AL56: =+AL38 -> 2030 Q4
F57: SaaS Tourism Revenue (USD million) | G57: 10653.967 | H57: 10973.98 | I57: 11303.604 | J57: 11643.13 | K57: 11992.854 | L57: 12353.083 | M57: 12724.132 | N57: 13106.326 | O57: 13500 | P57: 13905.499 | Q57: 14323.178 | R57: 14753.402 | S57: 15196.549 | T57: 15653.007 | U57: 16123.176 | V57: 16607.467 | W57: 17106.304 | X57: 17620.125 | Y57: 18149.38 | Z57: 18694.532 | AA57: 19256.059 | AB57: 19834.452 | AC57: 20430.218 | AD57: 21043.88 | AE57: 21675.974 | AF57: 22327.054 | AG57: 22997.69 | AH57: 23688.471 | AI57: 24400 | AJ57: 25132.902 | AK57: 25887.817 | AL57: 26665.408
G59: 0 | H59: =+(H57-G57)/G57 -> 0.030036947 | I59: =+(I57-H57)/H57 -> 0.030036947 | J59: =+(J57-I57)/I57 -> 0.030036947 | K59: =+(K57-J57)/J57 -> 0.030036947 | L59: =+(L57-K57)/K57 -> 0.030036947 | M59: =+(M57-L57)/L57 -> 0.030036947 | N59: =+(N57-M57)/M57 -> 0.030036947 | O59: =+(O57-N57)/N57 -> 0.030036947 | ... AL59: =+(AL57-AK57)/AK57 -> 0.030036947
H60: =+H59 -> 0.030036947 | I60: =+H60+I59 -> 0.060073894 | J60: =+I60+J59 -> 0.090110841 | K60: =+J60+K59 -> 0.12014779 | L60: =+K60+L59 -> 0.15018473 | M60: =+L60+M59 -> 0.18022168 | N60: =+M60+N59 -> 0.21025863 | O60: =+N60+O59 -> 0.24029557 | P60: =+O60+P59 -> 0.27033252 | ... AL60: =+AK60+AL59 -> 0.93114535
H63: 2023
...

Sheet Curva Dolar Blue
A1: category | B1: valor | I1: 44927 | J1: 178.1417 | K1: =+I1 -> 44927 | L1: =+SUMIFS($J$1:$J$574,$I$1:$I$574,K1) -> 178.1417
A2: =DATE(D2,B2,C2) -> 44928 | B2: 1 | C2: 2 | D2: 2023 | E2: 344 | F2: 44927 | G2: =+IF(SUMIFS($E$2:$E$575,$A$2:$A$575,F2)=0,G1,SUMIFS($E$2:$E$575,$A$2:$A$575,F2)) -> 0 | I2: 44928 | J2: 178.1417 | K2: =+K1+1 -> 44928 | L2: =+IF(SUMIFS($J$1:$J$1574,$I$1:$I$1574,K2)=0,L1,SUMIFS($J$1:$J$1574,$I$1:$I$1574,K2)) -> 178.1417 | Q2: 44927 | R2: 6 | S2: =+R2/100 -> 0.06
A3: =DATE(D3,B3,C3) -> 44929 | B3: 1 | C3: 3 | D3: 2023 | E3: 353 | F3: =F2+1 -> 44928 | G3: =+IF(SUMIFS($E$2:$E$1575,$A$2:$A$1575,F3)=0,G2,SUMIFS($E$2:$E$1575,$A$2:$A$1575,F3)) -> 344 | I3: 44929 | J3: 178.4317 | K3: =+K2+1 -> 44929 | L3: =+IF(SUMIFS($J$1:$J$574,$I$1:$I$574,K3)=0,L2,SUMIFS($J$1:$J$574,$I$1:$I$574,K3)) -> 178.4317 | Q3: 44958 | R3: 6.6 | S3: =+R3/100 -> 0.066
A4: =DATE(D4,B4,C4) -> 44930 | B4: 1 | C4: 4 | D4: 2023 | E4: 354 | F4: =F3+1 -> 44929 | G4: =+IF(SUMIFS($E$2:$E$1575,$A$2:$A$1575,F4)=0,G3,SUMIFS($E$2:$E$1575,$A$2:$A$1575,F4)) -> 353 | I4: 44930 | J4: 178.6533 | K4: =+K3+1 -> 44930 | L4: =+IF(SUMIFS($J$1:$J$574,$I$1:$I$574,K4)=0,L3,SUMIFS($J$1:$J$574,$I$1:$I$574,K4)) -> 178.6533 | Q4: 44986 | R4: 7.7 | S4: =+R4/100 -> 0.077
A5: =DATE(D5,B5,C5) -> 44931 | B5: 1 | C5: 5 | D5: 2023 | E5: 353 | F5: =F4+1 -> 44930 | G5: =+IF(SUMIFS($E$2:$E$1575,$A$2:$A$1575,F5)=0,G4,SUMIFS($E$2:$E$1575,$A$2:$A$1575,F5)) -> 354 | I5: 44931 | J5: 178.94 | K5: =+K4+1 -> 44931 | L5: =+IF(SUMIFS($J$1:$J$574,$I$1:$I$574,K5)=0,L4,SUMIFS($J$1:$J$574,$I$1:$I$574,K5)) -> 178.94 | Q5: 45017 | R5: 8.4 | S5: =+R5/100 -> 0.084
A6: =DATE(D6,B6,C6) -> 44932 | B6: 1 | C6: 6 | D6: 2023 | E6: 354 | F6: =F5+1 -> 44931 | G6: =+IF(SUMIFS($E$2:$E$1575,$A$2:$A$1575,F6)=0,G5,SUMIFS($E$2:$E$1575,$A$2:$A$1575,F6)) -> 353 | I6: 44932 | J6: 179.2433 | K6: =+K5+1 -> 44932 | L6: =+IF(SUMIFS($J$1:$J$574,$I$1:$I$574,K6)=0,L5,SUMIFS($J$1:$J$574,$I$1:$I$574,K6)) -> 179.2433 | Q6: 45047 | R6: 7.8 | S6: =+R6/100 -> 0.078
A7: =DATE(D7,B7,C7) -> 44935 | B7: 1 | C7: 9 | D7: 2023 | E7: 355 | F7: =F6+1 -> 44932 | G7: =+IF(SUMIFS($E$2:$E$1575,$A$2:$A$1575,F7)=0,G6,SUMIFS($E$2:$E$1575,$A$2:$A$1575,F7)) -> 354 | I7: 44935 | J7: 180.1367 | K7: =+K6+1 -> 44933 | L7: =+IF(SUMIFS($J$1:$J$1574,$I$1:$I$1574,K7)=0,L6,SUMIFS($J$1:$J$1574,$I$1:$I$1574,K7)) -> 179.2433 | Q7: 45078 | R7: 6 | S7: =+R7/100 -> 0.06
A8: =DATE(D8,B8,C8) -> 44936 | B8: 1 | C8: 10 | D8: 2023 | E8: 357 | F8: =F7+1 -> 44933 | G8: =+IF(SUMIFS($E$2:$E$1575,$A$2:$A$1575,F8)=0,G7,SUMIFS($E$2:$E$1575,$A$2:$A$1575,F8)) -> 354 | I8: 44936 | J8: 180.4017 | K8: =+K7+1 -> 44934 | L8: =+IF(SUMIFS($J$1:$J$1574,$I$1:$I$1574,K8)=0,L7,SUMIFS($J$1:$J$1574,$I$1:$I$1574,K8)) -> 179.2433 | Q8: 45108 | R8: 6.3 | S8: =+R8/100 -> 0.063
